Workbook

Sheet Metadata - 20250725
A1: SampleName | B1: WithCOI | C1: WithITS2 | D1: DoubleCheck | E1: Comments | F1: COISequence | G1: SpeciesNameCOIValidatedBefore20250725 | H1: COIValidated20250725 | I1: StandardizedSampleNameBefore20250725 | J1: StandardID20250725 | K1: SequencingBatch | L1: Sequencing run | M1: fastq_fwd_file_name | N1: fastq_rev_file_name | O1: Site | P1: Region | Q1: Latitude | R1: Longitude | S1: ApproximateShellLength | T1: Age | U1: CohortYear | V1: TransplantationYear | W1: TransplantationAge | X1: YearsSpentAtTransplantationSite | Y1: AdditionalSiteInfo | Z1: AdditionalComments
A2: SEM-Hh-1 | B2: =_xlfn.IFNA(VLOOKUP(I2,WithCOI!A:B,2,FALSE),"No COI") -> With COI | C2: =IF(_xlfn.IFNA(VLOOKUP(I2,WithITS2!A:A,1,FALSE),"None") = "None", "None","Yes") -> Yes | D2: =IF(AND(B2="No COI",C2="Yes"),"Double check","OK") -> OK | G2: Hh | H2: =G2 -> Hh | I2: HH01 | J2: HH01 | K2: Y2 | L2: HN00122531 | M2: SEM-Hh-1_1.fastq.gz | N2: SEM-Hh-1_2.fastq.gz | O2: Semirara | P2: Antique | Q2: 12.087081 | R2: 121.34602
A3: APO-B-Hh-1 | B3: =_xlfn.IFNA(VLOOKUP(I3,WithCOI!A:B,2,FALSE),"No COI") -> With COI | C3: =IF(_xlfn.IFNA(VLOOKUP(I3,WithITS2!A:A,1,FALSE),"None") = "None", "None","Yes") -> Yes | D3: =IF(AND(B3="No COI",C3="Yes"),"Double check","OK") -> OK | G3: Hh | H3: =G3 -> Hh | I3: HH02 | J3: HH02 | K3: Y2 | L3: HN00125113 | M3: APO-B-Hh-1_1.fastq.gz | N3: APO-B-Hh-1_2.fastq.gz | O3: Binanggaan | P3: ARNP | Q3: 12.6618 | R3: 120.43573
A4: APO-B-Hh-4 | B4: =_xlfn.IFNA(VLOOKUP(I4,WithCOI!A:B,2,FALSE),"No COI") -> With COI | C4: =IF(_xlfn.IFNA(VLOOKUP(I4,WithITS2!A:A,1,FALSE),"None") = "None", "None","Yes") -> Yes | D4: =IF(AND(B4="No COI",C4="Yes"),"Double check","OK") -> OK | G4: Hh | H4: =G4 -> Hh | I4: HH03 | J4: HH03 | K4: Y2 | L4: HN00125113 | M4: APO-B-Hh-4_1.fastq.gz | N4: APO-B-Hh-4_2.fastq.gz | O4: Binanggaan | P4: ARNP | Q4: 12.6618 | R4: 120.43573
A5: APO-B-Hp-4 | B5: =_xlfn.IFNA(VLOOKUP(I5,WithCOI!A:B,2,FALSE),"No COI") -> With COI | C5: =IF(_xlfn.IFNA(VLOOKUP(I5,WithITS2!A:A,1,FALSE),"None") = "None", "None","Yes") -> Yes | D5: =IF(AND(B5="No COI",C5="Yes"),"Double check","OK") -> OK | E5: Confirmed HH | F5: Yes | G5: Hh | H5: Hh | I5: HH05 | J5: HH05 | K5: Y2 | L5: HN00125113 | M5: APO-B-Hp-4_1.fastq.gz | N5: APO-B-Hp-4_2.fastq.gz | O5: Binanggaan | P5: ARNP | Q5: 12.6618 | R5: 120.43573
A6: SEM-Hh-2 | B6: =_xlfn.IFNA(VLOOKUP(I6,WithCOI!A:B,2,FALSE),"No COI") -> With COI | C6: =IF(_xlfn.IFNA(VLOOKUP(I6,WithITS2!A:A,1,FALSE),"None") = "None", "None","Yes") -> Yes | D6: =IF(AND(B6="No COI",C6="Yes"),"Double check","OK") -> OK | G6: Hh | H6: =G6 -> Hh | I6: HH06 | J6: HH06 | K6: Y2 | L6: HN00125113 | M6: SEM-Hh-2_1.fastq.gz | N6: SEM-Hh-2_2.fastq.gz | O6: Semirara | P6: Antique | Q6: 12.087081 | R6: 121.34602
A7: SEM-Hh-4 | B7: =_xlfn.IFNA(VLOOKUP(I7,WithCOI!A:B,2,FALSE),"No COI") -> With COI | C7: =IF(_xlfn.IFNA(VLOOKUP(I7,WithITS2!A:A,1,FALSE),"None") = "None", "None","Yes") -> Yes | D7: =IF(AND(B7="No COI",C7="Yes"),"Double check","OK") -> OK | G7: Hh | H7: =G7 -> Hh | I7: HH07 | J7: HH07 | K7: Y2 | L7: HN00125113 | M7: SEM-Hh-4_1.fastq.gz | N7: SEM-Hh-4_2.fastq.gz | O7: Semirara | P7: Antique | Q7: 12.087081 | R7: 121.34602
A8: Bohol_Hh_1 | B8: =_xlfn.IFNA(VLOOKUP(I8,WithCOI!A:B,2,FALSE),"No COI") -> With COI | C8: =IF(_xlfn.IFNA(VLOOKUP(I8,WithITS2!A:A,1,FALSE),"None") = "None", "None","Yes") -> Yes | D8: =IF(AND(B8="No COI",C8="Yes"),"Double check","OK") -> OK | G8: Hh | H8: =G8 -> Hh | I8: HH08 | J8: HH08 | K8: Y3 | L8: HN00138609 | M8: Bohol_Hh_1_1.fastq.gz | N8: Bohol_Hh_1_2.fastq.gz | O8: Bohol | P8: Bohol | Q8: 9.6287333 | R8: 123.80482
A9: Bohol_Hh_2 | B9: =_xlfn.IFNA(VLOOKUP(I9,WithCOI!A:B,2,FALSE),"No COI") -> With COI | C9: =IF(_xlfn.IFNA(VLOOKUP(I9,WithITS2!A:A,1,FALSE),"None") = "None", "None","Yes") -> Yes | D9: =IF(AND(B9="No COI",C9="Yes"),"Double check","OK") -> OK | G9: Hh | H9: =G9 -> Hh | I9: HH09 | J9: HH09 | K9: Y3 | L9: HN00138609 | M9: Bohol_Hh_2_1.fastq.gz | N9: Bohol_Hh_2_2.fastq.gz | O9: Bohol | P9: Bohol | Q9: 9.6287333 | R9: 123.80482
A10: Bohol_Hh_3 | B10: =_xlfn.IFNA(VLOOKUP(I10,WithCOI!A:B,2,FALSE),"No COI") -> With COI | C10: =IF(_xlfn.IFNA(VLOOKUP(I10,WithITS2!A:A,1,FALSE),"None") = "None", "None","Yes") -> Yes | D10: =IF(AND(B10="No COI",C10="Yes"),"Double check","OK") -> OK | G10: Hh | H10: =G10 -> Hh | I10: HH10 | J10: HH10 | K10: Y3 | L10: HN00138609 | M10: Bohol_Hh_3_1.fastq.gz | N10: Bohol_Hh_3_2.fastq.gz | O10: Bohol | P10: Bohol | Q10: 9.6287333 | R10: 123.80482
A11: Camiguin_Hh_1 | B11: =_xlfn.IFNA(VLOOKUP(I11,WithCOI!A:B,2,FALSE),"No COI") -> With COI | C11: =IF(_xlfn.IFNA(VLOOKUP(I11,WithITS2!A:A,1,FALSE),"None") = "None", "None","Yes") -> Yes | D11: =IF(AND(B11="No COI",C11="Yes"),"Double check","OK") -> OK | G11: Hh | H11: =G11 -> Hh | I11: HH11 | J11: HH11 | K11: Y3 | L11: HN00138609 | M11: Camiguin_Hh_1_1.fastq.gz | N11: Camiguin_Hh_1_2.fastq.gz | O11: Camiguin | P11: Camiguin | Q11: 9.1074134 | R11: 124.8032
A12: Camiguin_Hh_2 | B12: =_xlfn.IFNA(VLOOKUP(I12,WithCOI!A:B,2,FALSE),"No COI") -> With COI | C12: =IF(_xlfn.IFNA(VLOOKUP(I12,WithITS2!A:A,1,FALSE),"None") = "None", "None","Yes") -> Yes | D12: =IF(AND(B12="No COI",C12="Yes"),"Double check","OK") -> OK | G12: Hh | H12: =G12 -> Hh | I12: HH12 | J12: HH12 | K12: Y3 | L12: HN00138609 | M12: Camiguin_Hh_2_1.fastq.gz | N12: Camiguin_Hh_2_2.fastq.gz | O12: Camiguin | P12: Camiguin | Q12: 9.1074134 | R12: 124.8032
A13: Camiguin_Hh_3 | B13: =_xlfn.IFNA(VLOOKUP(I13,WithCOI!A:B,2,FALSE),"No COI") -> With COI | C13: =IF(_xlfn.IFNA(VLOOKUP(I13,WithITS2!A:A,1,FALSE),"None") = "None", "None","Yes") -> Yes | D13: =IF(AND(B13="No COI",C13="Yes"),"Double check","OK") -> OK | G13: Hh | H13: =G13 -> Hh | I13: HH13 | J13: HH13 | K13: Y3 | L13: HN00138609 | M13: Camiguin_Hh_3_1.fastq.gz | N13: Camiguin_Hh_3_2.fastq.gz | O13: Camiguin | P13: Camiguin | Q13: 9.1074134 | R13: 124.8032
A14: Samar_Hh_1 | B14: =_xlfn.IFNA(VLOOKUP(I14,WithCOI!A:B,2,FALSE),"No COI") -> With COI | C14: =IF(_xlfn.IFNA(VLOOKUP(I14,WithITS2!A:A,1,FALSE),"None") = "None", "None","Yes") -> Yes | D14: =IF(AND(B14="No COI",C14="Yes"),"Double check","OK") -> OK | G14: Hh | H14: =G14 -> Hh | I14: HH14 | J14: HH14 | K14: Y3 | L14: HN00138609 | M14: Samar_Hh_1_1.fastq.gz | N14: Samar_Hh_1_2.fastq.gz | O14: Guiuan | P14: Samar | Q14: 11.0583 | R14: 125.6537
A15: Samar_Hh_3 | B15: =_xlfn.IFNA(VLOOKUP(I15,WithCOI!A:B,2,FALSE),"No COI") -> With COI | C15: =IF(_xlfn.IFNA(VLOOKUP(I15,WithITS2!A:A,1,FALSE),"None") = "None", "None","Yes") -> Yes | D15: =IF(AND(B15="No COI",C15="Yes"),"Double check","OK") -> OK | G15: Hh | H15: =G15 -> Hh | I15: HH15 | J15: HH15 | K15: Y3 | L15: HN00138609 | M15: Samar_Hh_3_1.fastq.gz | N15: Samar_Hh_3_2.fastq.gz | O15: Guiuan | P15: Samar | Q15: 11.0583 | R15: 125.6537
A16: Samar_Hh_4 | B16: =_xlfn.IFNA(VLOOKUP(I16,WithCOI!A:B,2,FALSE),"No COI") -> With COI | C16: =IF(_xlfn.IFNA(VLOOKUP(I16,WithITS2!A:A,1,FALSE),"None") = "None", "None","Yes") -> Yes | D16: =IF(AND(B16="No COI",C16="Yes"),"Double check","OK") -> OK | G16: Hh | H16: =G16 -> Hh | I16: HH16 | J16: HH16 | K16: Y3 | L16: HN00138609 | M16: Samar_Hh_4_1.fastq.gz | N16: Samar_Hh_4_2.fastq.gz | O16: Guiuan | P16: Samar | Q16: 11.0583 | R16: 125.6537
A17: SIL_Hh_1 | B17: =_xlfn.IFNA(VLOOKUP(I17,WithCOI!A:B,2,FALSE),"No COI") -> With COI | C17: =IF(_xlfn.IFNA(VLOOKUP(I17,WithITS2!A:A,1,FALSE),"None") = "None", "None","Yes") -> Yes | D17: =IF(AND(B17="No COI",C17="Yes"),"Double check","OK") -> OK | G17: Hh | H17: =G17 -> Hh | I17: HH17 | J17: HH17 | K17: Y3 | L17: HN00147512 | M17: SIL_Hh_1_1.fastq.gz | N17: SIL_Hh_1_2.fastq.gz | O17: Silaqui | P17: Bolinao | Q17: 16.444117 | R17: 119.92153
... A19: SIL_Hh_3 | B19: =_xlfn.IFNA(VLOOKUP(I19,WithCOI!A:B,2,FALSE),"No COI") -> With COI | C19: =IF(_xlfn.IFNA(VLOOKUP(I19,WithITS2!A:A,1,FALSE),"None") = "None", "None","Yes") -> Yes | D19: =IF(AND(B19="No COI",C19="Yes"),"Double check","OK") -> OK | G19: Hh | H19: =G19 -> Hh | I19: HH19 | J19: HH19 | K19: Y3 | L19: HN00147512 | M19: SIL_Hh_3_1.fastq.gz | N19: SIL_Hh_3_2.fastq.gz | O19: Silaqui | P19: Bolinao | Q19: 16.444117 | R19: 119.92153
A20: APO-B-Hp-1 | B20: =_xlfn.IFNA(VLOOKUP(I20,WithCOI!A:B,2,FALSE),"No COI") -> With COI | C20: =IF(_xlfn.IFNA(VLOOKUP(I20,WithITS2!A:A,1,FALSE),"None") = "None", "None","Yes") -> Yes | D20: =IF(AND(B20="No COI",C20="Yes"),"Double check","OK") -> OK | E20: Confirmed HH | F20: Yes | G20: Hp | H20: Hh | I20: HP03 | J20: HH20 | K20: Y2 | L20: HN00125113 | M20: APO-B-Hp-1_1.fastq.gz | N20: APO-B-Hp-1_2.fastq.gz | O20: Binanggaan | P20: ARNP | Q20: 12.6618 | R20: 120.43573
A21: SEM-Hp-1 | B21: =_xlfn.IFNA(VLOOKUP(I21,WithCOI!A:B,2,FALSE),"No COI") -> With COI | C21: =IF(_xlfn.IFNA(VLOOKUP(I21,WithITS2!A:A,1,FALSE),"None") = "None", "None","Yes") -> Yes | D21: =IF(AND(B21="No COI",C21="Yes"),"Double check","OK") -> OK | G21: Hp | H21: =G21 -> Hp | I21: HP01 | J21: HP01 | K21: Y2 | L21: HN00122531 | M21: SEM-Hp-1_1.fastq.gz | N21: SEM-Hp-1_2.fastq.gz | O21: Semirara | P21: Antique | Q21: 12.087081 | R21: 121.34602
A22: SEM-Hp-2 | B22: =_xlfn.IFNA(VLOOKUP(I22,WithCOI!A:B,2,FALSE),"No COI") -> With COI | C22: =IF(_xlfn.IFNA(VLOOKUP(I22,WithITS2!A:A,1,FALSE),"None") = "None", "None","Yes") -> Yes | D22: =IF(AND(B22="No COI",C22="Yes"),"Double check","OK") -> OK | G22: Hp | H22: =G22 -> Hp | I22: HP02 | J22: HP02 | K22: Y2 | L22: HN00122531 | M22: SEM-Hp-2_1.fastq.gz | N22: SEM-Hp-2_2.fastq.gz | O22: Semirara | P22: Antique | Q22: 12.087081 | R22: 121.34602
A23: APO-B-Hp-6 | B23: =_xlfn.IFNA(VLOOKUP(I23,WithCOI!A:B,2,FALSE),"No COI") -> With COI | C23: =IF(_xlfn.IFNA(VLOOKUP(I23,WithITS2!A:A,1,FALSE),"None") = "None", "None","Yes") -> Yes | D23: =IF(AND(B23="No COI",C23="Yes"),"Double check","OK") -> OK | E23: Confirmed HP | F23: Yes | G23: Hp | H23: Hp | I23: HP04 | J23: HP04 | K23: Y2 | L23: HN00125113 | M23: APO-B-Hp-6_1.fastq.gz | N23: APO-B-Hp-6_2.fastq.gz | O23: Binanggaan | P23: ARNP | Q23: 12.6618 | R23: 120.43573
A24: SEM-Hp-4 | B24: =_xlfn.IFNA(VLOOKUP(I24,WithCOI!A:B,2,FALSE),"No COI") -> With COI | C24: =IF(_xlfn.IFNA(VLOOKUP(I24,WithITS2!A:A,1,FALSE),"None") = "None", "None","Yes") -> Yes | D24: =IF(AND(B24="No COI",C24="Yes"),"Double check","OK") -> OK | G24: Hp | H24: =G24 -> Hp | I24: HP05 | J24: HP05 | K24: Y2 | L24: HN00125113 | M24: SEM-Hp-4_1.fastq.gz | N24: SEM-Hp-4_2.fastq.gz | O24: Semirara | P24: Antique | Q24: 12.087081 | R24: 121.34602
A25: APO-B-Hh-6 | B25: =_xlfn.IFNA(VLOOKUP(I25,WithCOI!A:B,2,FALSE),"No COI") -> No COI | C25: =IF(_xlfn.IFNA(VLOOKUP(I25,WithITS2!A:A,1,FALSE),"None") = "None", "None","Yes") -> Yes | D25: =IF(AND(B25="No COI",C25="Yes"),"Double check","OK") -> Double check | E25: Confirmed TC | F25: Yes | G25: Hh | H25: Tc | I25: HH04 | J25: TC30 | K25: Y2 | L25: HN00125113 | M25: APO-B-Hh-6_1.fastq.gz | N25: APO-B-Hh-6_2.fastq.gz | O25: Binanggaan | P25: ARNP | Q25: 12.6618 | R25: 120.43573
A26: SEMIRARA-Tc-10 | B26: =_xlfn.IFNA(VLOOKUP(I26,WithCOI!A:B,2,FALSE),"No COI") -> No COI | C26: =IF(_xlfn.IFNA(VLOOKUP(I26,WithITS2!A:A,1,FALSE),"None") = "None", "None","Yes") -> None | D26: =IF(AND(B26="No COI",C26="Yes"),"Double check","OK") -> OK | G26: Tc | H26: =G26 -> Tc | I26: TC01 | J26: TC01 | K26: Y1 | L26: HN00102818 | M26: SEMIRARA-Tc-10_1.fastq.gz | N26: SEMIRARA-Tc-10_2.fastq.gz | O26: Semirara | P26: Antique | Q26: 12.087081 | R26: 121.34602
A27: SEMIRARA-Tc-7 | B27: =_xlfn.IFNA(VLOOKUP(I27,WithCOI!A:B,2,FALSE),"No COI") -> No COI | C27: =IF(_xlfn.IFNA(VLOOKUP(I27,WithITS2!A:A,1,FALSE),"None") = "None", "None","Yes") -> None | D27: =IF(AND(B27="No COI",C27="Yes"),"Double check","OK") -> OK | G27: Tc | H27: =G27 -> Tc | I27: TC02 | J27: TC02 | K27: Y1 | L27: HN00102818 | M27: SEMIRARA-Tc-7_1.fastq.gz | N27: SEMIRARA-Tc-7_2.fastq.gz | O27: Semirara | P27: Antique | Q27: 12.087081 | R27: 121.34602
A28: SEMIRARA-Tc-8 | B28: =_xlfn.IFNA(VLOOKUP(I28,WithCOI!A:B,2,FALSE),"No COI") -> No COI | C28: =IF(_xlfn.IFNA(VLOOKUP(I28,WithITS2!A:A,1,FALSE),"None") = "None", "None","Yes") -> None | D28: =IF(AND(B28="No COI",C28="Yes"),"Double check","OK") -> OK | G28: Tc | H28: =G28 -> Tc | I28: TC03 | J28: TC03 | K28: Y1 | L28: HN00102818 | M28: SEMIRARA-Tc-8_1.fastq.gz | N28: SEMIRARA-Tc-8_2.fastq.gz | O28: Semirara | P28: Antique | Q28: 12.087081 | R28: 121.34602
A29: SEMIRARA-Tm-3 | B29: =_xlfn.IFNA(VLOOKUP(I29,WithCOI!A:B,2,FALSE),"No COI") -> No COI | C29: =IF(_xlfn.IFNA(VLOOKUP(I29,WithITS2!A:A,1,FALSE),"None") = "None", "None","Yes") -> None | D29: =IF(AND(B29="No COI",C29="Yes"),"Double check","OK") -> OK | G29: Tc | H29: =G29 -> Tc | I29: TC04 | J29: TC04 | K29: Y1 | L29: HN00102818 | M29: SEMIRARA-Tm-3_1.fastq.gz | N29: SEMIRARA-Tm-3_2.fastq.gz | O29: Semirara | P29: Antique | Q29: 12.087081 | R29: 121.34602
A30: SEMIRARA-Tm-5 | B30: =_xlfn.IFNA(VLOOKUP(I30,WithCOI!A:B,2,FALSE),"No COI") -> No COI | C30: =IF(_xlfn.IFNA(VLOOKUP(I30,WithITS2!A:A,1,FALSE),"None") = "None", "None","Yes") -> None | D30: =IF(AND(B30="No COI",C30="Yes"),"Double check","OK") -> OK | G30: Tc | H30: =G30 -> Tc | I30: TC05 | J30: TC05 | K30: Y1 | L30: HN00102818 | M30: SEMIRARA-Tm-5_1.fastq.gz | N30: SEMIRARA-Tm-5_2.fastq.gz | O30: Semirara | P30: Antique | Q30: 12.087081 | R30: 121.34602
A31: APO-SA-Tc-3 | B31: =_xlfn.IFNA(VLOOKUP(I31,WithCOI!A:B,2,FALSE),"No COI") -> With COI | C31: =IF(_xlfn.IFNA(VLOOKUP(I31,WithITS2!A:A,1,FALSE),"None") = "None", "None","Yes") -> Yes | D31: =IF(AND(B31="No COI",C31="Yes"),"Double check","OK") -> OK | G31: Tc | H31: =G31 -> Tc | I31: TC06 | J31: TC06 | K31: Y2 | L31: HN00122531 | M31: APO-SA-Tc-3_1.fastq.gz | N31: APO-SA-Tc-3_2.fastq.gz | O31: South Atoll | P31: ARNP | Q31: 12.639567 | R31: 120.45162
A32: APO-SA-Tc-5 | B32: =_xlfn.IFNA(VLOOKUP(I32,WithCOI!A:B,2,FALSE),"No COI") -> With COI | C32: =IF(_xlfn.IFNA(VLOOKUP(I32,WithITS2!A:A,1,FALSE),"None") = "None", "None","Yes") -> Yes | D32: =IF(AND(B32="No COI",C32="Yes"),"Double check","OK") -> OK | G32: Tc | H32: =G32 -> Tc | I32: TC07 | J32: TC07 | K32: Y2 | L32: HN00122531 | M32: APO-SA-Tc-5_1.fastq.gz | N32: APO-SA-Tc-5_2.fastq.gz | O32: South Atoll | P32: ARNP | Q32: 12.639567 | R32: 120.45162
A33: MAS-Tc-2 | B33: =_xlfn.IFNA(VLOOKUP(I33,WithCOI!A:B,2,FALSE),"No COI") -> With COI | C33: =IF(_xlfn.IFNA(VLOOKUP(I33,WithITS2!A:A,1,FALSE),"None") = "None", "None","Yes") -> Yes | D33: =IF(AND(B33="No COI",C33="Yes"),"Double check","OK") -> OK | G33: Tc | H33: =G33 -> Tc | I33: TC08 | J33: TC08 | K33: Y2 | L33: HN00122531 | M33: MAS-Tc-2_1.fastq.gz | N33: MAS-Tc-2_2.fastq.gz | O33: Masinloc | P33: Zambales | Q33: 15.529867 | R33: 119.92482
A34: MAS-Tc-3 | B34: =_xlfn.IFNA(VLOOKUP(I34,WithCOI!A:B,2,FALSE),"No COI") -> With COI | C34: =IF(_xlfn.IFNA(VLOOKUP(I34,WithITS2!A:A,1,FALSE),"None") = "None", "None","Yes") -> Yes | D34: =IF(AND(B34="No COI",C34="Yes"),"Double check","OK") -> OK | G34: Tc | H34: =G34 -> Tc | I34: TC09 | J34: TC09 | K34: Y2 | L34: HN00122531 | M34: MAS-Tc-3_1.fastq.gz | N34: MAS-Tc-3_2.fastq.gz | O34: Masinloc | P34: Zambales | Q34: 15.529867 | R34: 119.92482
A35: MAS-Tc-4 | B35: =_xlfn.IFNA(VLOOKUP(I35,WithCOI!A:B,2,FALSE),"No COI") -> With COI | C35: =IF(_xlfn.IFNA(VLOOKUP(I35,WithITS2!A:A,1,FALSE),"None") = "None", "None","Yes") -> Yes | D35: =IF(AND(B35="No COI",C35="Yes"),"Double check","OK") -> OK | G35: Tc | H35: =G35 -> Tc | I35: TC10 | J35: TC10 | K35: Y2 | L35: HN00122531 | M35: MAS-Tc-4_1.fastq.gz | N35: MAS-Tc-4_2.fastq.gz | O35: Masinloc | P35: Zambales | Q35: 15.529867 | R35: 119.92482
A36: MAS-Tm-1 | B36: =_xlfn.IFNA(VLOOKUP(I36,WithCOI!A:B,2,FALSE),"No COI") -> With COI | C36: =IF(_xlfn.IFNA(VLOOKUP(I36,WithITS2!A:A,1,FALSE),"None") = "None", "None","Yes") -> Yes | D36: =IF(AND(B36="No COI",C36="Yes"),"Double check","OK") -> OK | G36: Tc | H36: =G36 -> Tc | I36: TC11 | J36: TC11 | K36: Y2 | L36: HN00122531 | M36: MAS-Tm-1_1.fastq.gz | N36: MAS-Tm-1_2.fastq.gz | O36: Masinloc | P36: Zambales | Q36: 15.529867 | R36: 119.92482
A37: MAS-Tm-2 | B37: =_xlfn.IFNA(VLOOKUP(I37,WithCOI!A:B,2,FALSE),"No COI") -> With COI | C37: =IF(_xlfn.IFNA(VLOOKUP(I37,WithITS2!A:A,1,FALSE),"None") = "None", "None","Yes") -> Yes | D37: =IF(AND(B37="No COI",C37="Yes"),"Double check","OK") -> OK | G37: Tc | H37: =G37 -> Tc | I37: TC12 | J37: TC12 | K37: Y2 | L37: HN00122531 | M37: MAS-Tm-2_1.fastq.gz | N37: MAS-Tm-2_2.fastq.gz | O37: Masinloc | P37: Zambales | Q37: 15.529867 | R37: 119.92482
... A72: SIL_Td_3 | B72: =_xlfn.IFNA(VLOOKUP(I72,WithCOI!A:B,2,FALSE),"No COI") -> With COI | C72: =IF(_xlfn.IFNA(VLOOKUP(I72,WithITS2!A:A,1,FALSE),"None") = "None", "None","Yes") -> Yes | D72: =IF(AND(B72="No COI",C72="Yes"),"Double check","OK") -> OK | G72: Td | H72: =G72 -> Td | I72: TD18 | J72: TD18 | K72: Y3 | L72: HN00147512 | M72: SIL_Td_3_1.fastq.gz | N72: SIL_Td_3_2.fastq.gz | O72: Silaqui | P72: Bolinao | Q72: 16.444117 | R72: 119.92153
A73: ALAMINOS-Tg-2 | B73: =_xlfn.IFNA(VLOOKUP(I73,WithCOI!A:B,2,FALSE),"No COI") -> No COI | C73: =IF(_xlfn.IFNA(VLOOKUP(I73,WithITS2!A:A,1,FALSE),"None") = "None", "None","Yes") -> None | D73: =IF(AND(B73="No COI",C73="Yes"),"Double check","OK") -> OK | G73: Tg | H73: =G73 -> Tg | I73: TG01 | J73: TG01 | K73: Y1 | L73: HN00102818 | M73: ALAMINOS-Tg-2_1.fastq.gz | N73: ALAMINOS-Tg-2_2.fastq.gz | O73: HINP | P73: Alaminos | Q73: 16.221833 | R73: 120.04842 | S73: 80 | T73: 23 | U73: 1995 | V73: 1998 | W73: 20 | X73: 3 | Y73: HINP
A74: ALAMINOS-Tg-3 | B74: =_xlfn.IFNA(VLOOKUP(I74,WithCOI!A:B,2,FALSE),"No COI") -> No COI | C74: =IF(_xlfn.IFNA(VLOOKUP(I74,WithITS2!A:A,1,FALSE),"None") = "None", "None","Yes") -> None | D74: =IF(AND(B74="No COI",C74="Yes"),"Double check","OK") -> OK | G74: Tg | H74: =G74 -> Tg | I74: TG02 | J74: TG02 | K74: Y1 | L74: HN00102818 | M74: ALAMINOS-Tg-3_1.fastq.gz | N74: ALAMINOS-Tg-3_2.fastq.gz | O74: HINP | P74: Alaminos | Q74: 16.221833 | R74: 120.04842 | S74: 71 | T74: 23 | U74: 1995 | V74: 1998 | W74: 20 | X74: 3 | Y74: HINP
A75: ALAMINOS-Tg-5 | B75: =_xlfn.IFNA(VLOOKUP(I75,WithCOI!A:B,2,FALSE),"No COI") -> No COI | C75: =IF(_xlfn.IFNA(VLOOKUP(I75,WithITS2!A:A,1,FALSE),"None") = "None", "None","Yes") -> None | D75: =IF(AND(B75="No COI",C75="Yes"),"Double check","OK") -> OK | G75: Tg | H75: =G75 -> Tg | I75: TG03 | J75: TG03 | K75: Y1 | L75: HN00102818 | M75: ALAMINOS-Tg-5_1.fastq.gz | N75: ALAMINOS-Tg-5_2.fastq.gz | O75: HINP | P75: Alaminos | Q75: 16.221833 | R75: 120.04842 | S75: 90 | T75: 23 | U75: 1995 | V75: 1998 | W75: 20 | X75: 3 | Y75: HINP
...

Sheet WithCOI
A1: SampleID | B1: Comments
A2: TM24 | B2: With COI
A3: HH06 | B3: With COI
A4: HH12 | B4: With COI
A5: TS24 | B5: With COI
A6: TS25 | B6: With COI
A7: TS22 | B7: With COI
A8: TS23 | B8: With COI
A9: TS21 | B9: With COI
A10: HH09 | B10: With COI
A11: TN11 | B11: With COI
A12: TS26 | B12: With COI
... A160: TS19 | B160: With COI

Sheet WithITS2
A1: TM24
A2: HH06
A3: HH12
A4: TS24
A5: TS25
A6: TS22
A7: TS23
A8: TS21
A9: HH09
A10: TN11
A11: TS26
A12: TN06
... A159: TS19
